2018-09-18T17:51:33|CRITICAL|root|Unhandled exception:Traceback (most recent call last):
  File "C:\Users\user\Anaconda3\lib\site-packages\ScopeFoundry\hardware.py", line 208, in enable_connection
    raise err
  File "C:\Users\user\Anaconda3\lib\site-packages\ScopeFoundry\hardware.py", line 204, in enable_connection
    self.connect()
  File "C:\Users\user\eclipse-workspace\Shutter\shutter_hw.py", line 21, in connect
    print(self.settings['shutter_closed'])
  File "C:\Users\user\Anaconda3\lib\site-packages\ScopeFoundry\logged_quantity.py", line 1148, in __getitem__
    return self._logged_quantities[key].val
KeyError: 'shutter_closed'

