2018-09-18T15:24:51|CRITICAL|root|Unhandled exception:Traceback (most recent call last):
  File "C:\Users\user\Anaconda3\lib\site-packages\ScopeFoundry\hardware.py", line 208, in enable_connection
    raise err
  File "C:\Users\user\Anaconda3\lib\site-packages\ScopeFoundry\hardware.py", line 204, in enable_connection
    self.connect()
  File "C:\Users\user\Anaconda3\lib\site-packages\Shutter\shutter_hw.py", line 20, in connect
    self.shutter = ShutterDevice(port = self.port.val, debug=self.debug_mode.val)
  File "C:\Users\user\eclipse-workspace\Shutter\shutter_device.py", line 15, in __init__
    ,parity='N', stopbits=1, xonxoff=True)
  File "C:\Users\user\Anaconda3\lib\site-packages\serial\serialwin32.py", line 31, in __init__
    super(Serial, self).__init__(*args, **kwargs)
  File "C:\Users\user\Anaconda3\lib\site-packages\serial\serialutil.py", line 240, in __init__
    self.open()
  File "C:\Users\user\Anaconda3\lib\site-packages\serial\serialwin32.py", line 62, in open
    raise SerialException("could not open port {!r}: {!r}".format(self.portstr, ctypes.WinError()))
serial.serialutil.SerialException: could not open port 'COM5': FileNotFoundError(2, 'Impossibile trovare il file specificato.', None, 2)

2018-09-18T15:29:27|WARNING|LoggedQuantity|sine_data read_from_hardware called when not connected to hardware
2018-09-18T15:29:27|WARNING|LoggedQuantity|sine_data read_from_hardware called when not connected to hardware
