2019-01-23T11:07:54|CRITICAL|root|Unhandled exception:Traceback (most recent call last):
  File "C:\ProgramData\Anaconda3\lib\site-packages\ScopeFoundry\hardware.py", line 208, in enable_connection
    raise err
  File "C:\ProgramData\Anaconda3\lib\site-packages\ScopeFoundry\hardware.py", line 204, in enable_connection
    self.connect()
  File "C:\LabPrograms\Python\Shutter\shutter_hw.py", line 39, in connect
    self.shutter = ShutterDevice(port = self.port.val, debug=self.debug_mode.val)
  File "C:\LabPrograms\Python\Shutter\shutter_device.py", line 38, in __init__
    ,parity='N', stopbits=1, xonxoff=True)       #that define the parameters for the
  File "C:\ProgramData\Anaconda3\lib\site-packages\serial\serialwin32.py", line 31, in __init__
    super(Serial, self).__init__(*args, **kwargs)
  File "C:\ProgramData\Anaconda3\lib\site-packages\serial\serialutil.py", line 240, in __init__
    self.open()
  File "C:\ProgramData\Anaconda3\lib\site-packages\serial\serialwin32.py", line 62, in open
    raise SerialException("could not open port {!r}: {!r}".format(self.portstr, ctypes.WinError()))
serial.serialutil.SerialException: could not open port 'COM5': FileNotFoundError(2, 'Impossibile trovare il file specificato.', None, 2)

2019-01-23T11:07:57|CRITICAL|root|Unhandled exception:Traceback (most recent call last):
  File "C:\ProgramData\Anaconda3\lib\site-packages\ScopeFoundry\hardware.py", line 208, in enable_connection
    raise err
  File "C:\ProgramData\Anaconda3\lib\site-packages\ScopeFoundry\hardware.py", line 204, in enable_connection
    self.connect()
  File "C:\LabPrograms\Python\Shutter\shutter_hw.py", line 39, in connect
    self.shutter = ShutterDevice(port = self.port.val, debug=self.debug_mode.val)
  File "C:\LabPrograms\Python\Shutter\shutter_device.py", line 38, in __init__
    ,parity='N', stopbits=1, xonxoff=True)       #that define the parameters for the
  File "C:\ProgramData\Anaconda3\lib\site-packages\serial\serialwin32.py", line 31, in __init__
    super(Serial, self).__init__(*args, **kwargs)
  File "C:\ProgramData\Anaconda3\lib\site-packages\serial\serialutil.py", line 240, in __init__
    self.open()
  File "C:\ProgramData\Anaconda3\lib\site-packages\serial\serialwin32.py", line 62, in open
    raise SerialException("could not open port {!r}: {!r}".format(self.portstr, ctypes.WinError()))
serial.serialutil.SerialException: could not open port 'COM5': FileNotFoundError(2, 'Impossibile trovare il file specificato.', None, 2)

